Workbook

Sheet Start
A1: Falcon Tax Solutions · 2026 Tax Organizer
A2: Fill this out at home, then upload it to get your estimate.
B4: How it works
B5: 1. Fill in the YELLOW cells on each tab, left to right: Household, Jobs, Income, Expenses, Trips, Payments, Checklist.
B6: 2. Grey rows show an example of what to enter. Leave them as they are.
B7: 3. Skip any tab that doesn't apply to you. Blank cells count as zero.
B8: 4. Save the file (Excel: .xlsx; Google Sheets: File > Download > Microsoft Excel).
B9: 5. Upload it on our Refund Estimator page. You'll see your estimated federal and state refund or amount due right away.
B11: Privacy
B12: Do NOT enter Social Security numbers, bank account numbers or passwords in this file.
B13: When you upload it, the file is read on your own device and is not sent to us. We collect IDs and documents only through our secure portal.
B15: Good to know
B16: This is an estimate for the 2026 tax year (returns filed in 2027), not a filed return or a promise of any refund.
B17: Married filing jointly: include both spouses' income. Married filing separately: include only your own.
... B24: Blue: calculated for you

Sheet Household
A1: Household
A2: Filing status, state, and the people on your return.
A4: Filing status | C4: Choose from the list.
A5: State you lived in during 2026 | C5: Choose from the list.
A6: Your birth year | C6: Example: 1985
A7: Spouse's birth year | C7: Married filing jointly only.
A8: Did you pay for childcare so you could work? | C8: Yes or No
A11: Dependents (children and relatives you support)
A12: First name | B12: Relationship | C12: Birth year | D12: Months lived with you | E12: Has an SSN? (Yes/No)
A13: Example: Maya | B13: Daughter | C13: 2016 | D13: 12 | E13: Yes
A25: Children under 17 at the end of 2026 were born in 2010 or later. Leave this table empty if you have no dependents.

Sheet Jobs
A1: Jobs (W-2 paychecks)
A2: One row per W-2. Use the final pay stub of the year if you don't have the W-2 yet.
A4: Employer | B4: Whose job (You / Spouse) | C4: Wages (W-2 box 1) | D4: Federal tax withheld (box 2) | E4: State tax withheld (box 17) | F4: Tips on W-2 (box 7) | G4: Overtime premium (extra half only)
A5: Example: ABC Logistics | B5: You | C5: 52000 | D5: 5200 | E5: 2400 | F5: 0 | G5: 1500
A16: Total | C16: =SUM(C6:C15) -> 0 | D16: =SUM(D6:D15) -> 0 | E16: =SUM(E6:E15) -> 0 | F16: =SUM(F6:F15) -> 0 | G16: =SUM(G6:G15) -> 0
A18: Overtime premium: only the extra 'half' of time-and-a-half (up to $12,500, or $25,000 joint, may be deductible). Cash tips you did NOT report to your employer go on the Income tab.

Sheet Income
A1: Self-employment, cash & other income
A2: Business income, cash payments, and income not on a W-2.
A4: Self-employment & cash income (1099-NEC, 1099-K, cash, Zelle, checks)
A5: Payer or description | B5: Type | C5: Amount received
A6: Example: Uber (1099-K) | B6: 1099-K | C6: 38000
A19: Total self-employment income | C19: =SUM(C7:C18) -> 0
A20: Report all business income, including cash and app payments, even if you didn't get a 1099.
A22: Other income
A23: Type | B23: Form | C23: Amount
A24: Cash tips NOT reported to your employer | B24: Tip log
A25: Bank interest | B25: 1099-INT
A26: Unemployment benefits | B26: 1099-G
A27: Retirement withdrawals (taxable amount) | B27: 1099-R
A28: Other taxable income (prizes, rental profit, etc.)

Sheet Expenses
A1: Business expenses
A2: Self-employed only. Enter what you paid in 2026; the deductible amount is calculated.
A4: Expense | B4: Schedule C line | C4: Amount paid | D4: Deductible share | E4: Deductible amount | F4: Notes
A5: Example: Fuel (diesel) | B5: 9 | C5: 1250 | D5: 1 | E5: 1250
A6: GENERAL BUSINESS
A7: Advertising & marketing | B7: 8 | D7: 1 | E7: =C7*D7 -> 0
A8: Car & truck (non-trucking business vehicle) | B8: 9 | D8: 1 | E8: =C8*D8 -> 0 | F8: Business-use share only; keep a mileage log.
A9: Bank, payment & platform fees | B9: 10 | D9: 1 | E9: =C9*D9 -> 0
A10: Contract labor (1099 workers) | B10: 11 | D10: 1 | E10: =C10*D10 -> 0 | F10: Send 1099-NEC to anyone paid $2,000+ in 2026.
A11: Business insurance | B11: 15 | D11: 1 | E11: =C11*D11 -> 0
A12: Interest on business loans | B12: 16b | D12: 1 | E12: =C12*D12 -> 0
A13: Legal & professional fees | B13: 17 | D13: 1 | E13: =C13*D13 -> 0
A14: Office expense & supplies | B14: 18 | D14: 1 | E14: =C14*D14 -> 0
A15: Rent (office, equipment) | B15: 20b | D15: 1 | E15: =C15*D15 -> 0
A16: Taxes & licenses | B16: 23 | D16: 1 | E16: =C16*D16 -> 0
A17: Travel (overnight trips) | B17: 24a | D17: 1 | E17: =C17*D17 -> 0
A18: Business meals (enter full amount) | B18: 24b | D18: 0.5 | E18: =C18*D18 -> 0 | F18: Only 50% is deductible. Truck drivers: use the Trips tab instead.
A19: Phone & internet (business share) | B19: 25 | D19: 1 | E19: =C19*D19 -> 0 | F19: Business-use percentage only.
A20: Software & subscriptions | B20: 27a | D20: 1 | E20: =C20*D20 -> 0
A21: Materials & supplies used for jobs | B21: 22 | D21: 1 | E21: =C21*D21 -> 0 | F21: Parts and materials you buy for customers' jobs.
A22: Tools & equipment (under $2,500 each) | B22: 22 | D22: 1 | E22: =C22*D22 -> 0 | F22: Larger items may need depreciation.
A23: Equipment rental | B23: 20a | D23: 1 | E23: =C23*D23 -> 0
A24: Repairs (business equipment, non-vehicle) | B24: 21 | D24: 1 | E24: =C24*D24 -> 0
A25: Uniforms & safety gear | B25: 27a | D25: 1 | E25: =C25*D25 -> 0 | F25: Only clothing not suitable for everyday wear.
A26: Postage & shipping | B26: 18 | D26: 1 | E26: =C26*D26 -> 0
A27: Utilities (business location) | B27: 25 | D27: 1 | E27: =C27*D27 -> 0
A28: Training, courses & licenses for your trade | B28: 27a | D28: 1 | E28: =C28*D28 -> 0
A29: Business gifts (up to $25 per person) | B29: 27a | D29: 1 | E29: =C29*D29 -> 0
A30: Home office (we calculate the deductible part) | B30: 30 | D30: 0 | E30: =C30*D30 -> 0 | F30: Enter total rent/utilities for the home; we figure the business share (Form 8829).
A31: TRUCKING
A32: Fuel (diesel) | B32: 9 | D32: 1 | E32: =C32*D32 -> 0
A33: DEF fluid | B33: 9 | D33: 1 | E33: =C33*D33 -> 0
A34: IFTA fuel tax paid | B34: 23 | D34: 1 | E34: =C34*D34 -> 0
A35: IFTA license & decals | B35: 23 | D35: 1 | E35: =C35*D35 -> 0
A36: Form 2290 heavy vehicle use tax | B36: 23 | D36: 1 | E36: =C36*D36 -> 0
A37: IRP plates & registration | B37: 23 | D37: 1 | E37: =C37*D37 -> 0
A38: UCR registration | B38: 23 | D38: 1 | E38: =C38*D38 -> 0
A39: Permits (trip, fuel, oversize/overweight) | B39: 23 | D39: 1 | E39: =C39*D39 -> 0
A40: State road taxes (NY HUT, KYU, NM WDT, OR) | B40: 23 | D40: 1 | E40: =C40*D40 -> 0
A41: Truck insurance (liability, cargo, physical damage) | B41: 15 | D41: 1 | E41: =C41*D41 -> 0
...

Sheet Trips
A1: Truck driver trips (per diem)
A2: Self-employed drivers away from home overnight. One row per trip.
A4: Left home (date) | B4: Got back (date) | C4: Full days in Canada | D4: Full days away | E4: Travel days (75%) | F4: Per diem
A5: 2026-03-02 | B5: 2026-03-09 | C5: 0 | D5: 6 | E5: 2 | F5: 600
D6: =IF(AND(ISNUMBER(A6),ISNUMBER(B6),B6>A6),B6-A6-1,0) -> 0 | E6: =IF(AND(ISNUMBER(A6),ISNUMBER(B6),B6>A6),2,0) -> 0 | F6: =(D6-MIN(C6,D6))*Data!$C$40+MIN(C6,D6)*Data!$C$41+E6*Data!$C$40*Data!$C$42 -> 0
D7: =IF(AND(ISNUMBER(A7),ISNUMBER(B7),B7>A7),B7-A7-1,0) -> 0 | E7: =IF(AND(ISNUMBER(A7),ISNUMBER(B7),B7>A7),2,0) -> 0 | F7: =(D7-MIN(C7,D7))*Data!$C$40+MIN(C7,D7)*Data!$C$41+E7*Data!$C$40*Data!$C$42 -> 0
D8: =IF(AND(ISNUMBER(A8),ISNUMBER(B8),B8>A8),B8-A8-1,0) -> 0 | E8: =IF(AND(ISNUMBER(A8),ISNUMBER(B8),B8>A8),2,0) -> 0 | F8: =(D8-MIN(C8,D8))*Data!$C$40+MIN(C8,D8)*Data!$C$41+E8*Data!$C$40*Data!$C$42 -> 0
D9: =IF(AND(ISNUMBER(A9),ISNUMBER(B9),B9>A9),B9-A9-1,0) -> 0 | E9: =IF(AND(ISNUMBER(A9),ISNUMBER(B9),B9>A9),2,0) -> 0 | F9: =(D9-MIN(C9,D9))*Data!$C$40+MIN(C9,D9)*Data!$C$41+E9*Data!$C$40*Data!$C$42 -> 0
D10: =IF(AND(ISNUMBER(A10),ISNUMBER(B10),B10>A10),B10-A10-1,0) -> 0 | E10: =IF(AND(ISNUMBER(A10),ISNUMBER(B10),B10>A10),2,0) -> 0 | F10: =(D10-MIN(C10,D10))*Data!$C$40+MIN(C10,D10)*Data!$C$41+E10*Data!$C$40*Data!$C$42 -> 0
D11: =IF(AND(ISNUMBER(A11),ISNUMBER(B11),B11>A11),B11-A11-1,0) -> 0 | E11: =IF(AND(ISNUMBER(A11),ISNUMBER(B11),B11>A11),2,0) -> 0 | F11: =(D11-MIN(C11,D11))*Data!$C$40+MIN(C11,D11)*Data!$C$41+E11*Data!$C$40*Data!$C$42 -> 0
D12: =IF(AND(ISNUMBER(A12),ISNUMBER(B12),B12>A12),B12-A12-1,0) -> 0 | E12: =IF(AND(ISNUMBER(A12),ISNUMBER(B12),B12>A12),2,0) -> 0 | F12: =(D12-MIN(C12,D12))*Data!$C$40+MIN(C12,D12)*Data!$C$41+E12*Data!$C$40*Data!$C$42 -> 0
D13: =IF(AND(ISNUMBER(A13),ISNUMBER(B13),B13>A13),B13-A13-1,0) -> 0 | E13: =IF(AND(ISNUMBER(A13),ISNUMBER(B13),B13>A13),2,0) -> 0 | F13: =(D13-MIN(C13,D13))*Data!$C$40+MIN(C13,D13)*Data!$C$41+E13*Data!$C$40*Data!$C$42 -> 0
D14: =IF(AND(ISNUMBER(A14),ISNUMBER(B14),B14>A14),B14-A14-1,0) -> 0 | E14: =IF(AND(ISNUMBER(A14),ISNUMBER(B14),B14>A14),2,0) -> 0 | F14: =(D14-MIN(C14,D14))*Data!$C$40+MIN(C14,D14)*Data!$C$41+E14*Data!$C$40*Data!$C$42 -> 0
D15: =IF(AND(ISNUMBER(A15),ISNUMBER(B15),B15>A15),B15-A15-1,0) -> 0 | E15: =IF(AND(ISNUMBER(A15),ISNUMBER(B15),B15>A15),2,0) -> 0 | F15: =(D15-MIN(C15,D15))*Data!$C$40+MIN(C15,D15)*Data!$C$41+E15*Data!$C$40*Data!$C$42 -> 0
D16: =IF(AND(ISNUMBER(A16),ISNUMBER(B16),B16>A16),B16-A16-1,0) -> 0 | E16: =IF(AND(ISNUMBER(A16),ISNUMBER(B16),B16>A16),2,0) -> 0 | F16: =(D16-MIN(C16,D16))*Data!$C$40+MIN(C16,D16)*Data!$C$41+E16*Data!$C$40*Data!$C$42 -> 0
D17: =IF(AND(ISNUMBER(A17),ISNUMBER(B17),B17>A17),B17-A17-1,0) -> 0 | E17: =IF(AND(ISNUMBER(A17),ISNUMBER(B17),B17>A17),2,0) -> 0 | F17: =(D17-MIN(C17,D17))*Data!$C$40+MIN(C17,D17)*Data!$C$41+E17*Data!$C$40*Data!$C$42 -> 0
... D35: =IF(AND(ISNUMBER(A35),ISNUMBER(B35),B35>A35),B35-A35-1,0) -> 0 | E35: =IF(AND(ISNUMBER(A35),ISNUMBER(B35),B35>A35),2,0) -> 0 | F35: =(D35-MIN(C35,D35))*Data!$C$40+MIN(C35,D35)*Data!$C$41+E35*Data!$C$40*Data!$C$42 -> 0
A36: Total | C36: =SUM(C6:C35) -> 0 | D36: =SUM(D6:D35) -> 0 | E36: =SUM(E6:E35) -> 0 | F36: =SUM(F6:F35) -> 0
E37: Deductible (80%) | F37: =F36*Data!$C$43 -> 0
A39: IRS transportation per diem (Notice 2026-60): $80/day in the U.S., $86 in Canada. The day you leave and the day you return count at 75%. Drivers under DOT hours-of-service rules deduct 80%. Employee (W-2) drivers can't deduct this on their federal return. Keep your logbook or ELD records.

Sheet Payments
A1: Estimated tax payments
A2: Quarterly payments you sent to the IRS or your state for 2026.
A4: Quarter | B4: Federal paid | C4: Date paid | D4: State paid | E4: Date paid
A5: Q1 (due Apr 15, 2026)
A6: Q2 (due Jun 15, 2026)
A7: Q3 (due Sep 15, 2026)
A8: Q4 (due Jan 15, 2027)
A9: Total | B9: =SUM(B5:B8) -> 0 | D9: =SUM(D5:D8) -> 0

Sheet Checklist
A1: Checklist
A2: Answer Yes or No. These help us find credits and documents.
A4: Did you sell stocks or crypto, or receive dividends?
A5: Did you pay mortgage interest on your home?
A6: Did you pay student loan interest?
A7: Did you pay college tuition for yourself or a dependent?
A8: Did anyone on your return have Marketplace health insurance (Form 1095-A)?
A9: Does anyone on the return NOT have a Social Security number?
A10: Did you receive a letter from the IRS or the state?

Sheet Data
A1: Data for the estimator | E1: Filing status | F1: Code | H1: State | I1: Code
A2: Calculated from your answers. Please don't change this tab. | E2: Single | F2: single | H2: Alabama | I2: AL
A3: Key | B3: Meaning | C3: Value | E3: Married filing jointly | F3: mfj | H3: Alaska | I3: AK
A4: format | B4: Organizer version | C4: ="falcon-organizer-2026" -> falcon-organizer-2026 | E4: Married filing separately | F4: mfs | H4: Arizona | I4: AZ
A5: status | B5: Filing status code | C5: =IFERROR(INDEX($F$2:$F$5,MATCH(Household!B4,$E$2:$E$5,0)),"single") -> single | E5: Head of household | F5: hoh | H5: Arkansas | I5: AR
A6: state | B6: State code | C6: =IFERROR(INDEX($I$2:$I$52,MATCH(Household!B5,$H$2:$H$52,0)),"") | H6: California | I6: CA
A7: you65 | B7: You are 65 or older (born 1961 or earlier) | C7: =IF(AND(ISNUMBER(Household!B6),Household!B6>0,Household!B6<=1961),1,0) -> 0 | H7: Colorado | I7: CO
A8: spouse65 | B8: Spouse is 65 or older (joint returns) | C8: =IF(AND(C5="mfj",ISNUMBER(Household!B7),Household!B7>0,Household!B7<=1961),1,0) -> 0 | H8: Connecticut | I8: CT
A9: childrenUnder17 | B9: Children under 17 (born 2010 or later) | C9: =COUNTIFS(Household!A14:A23,"?*",Household!C14:C23,">=2010") -> 0 | H9: Delaware | I9: DE
A10: otherDependents | B10: Other dependents | C10: =COUNTIF(Household!A14:A23,"?*")-C9 -> 0 | H10: District of Columbia | I10: DC
A11: hasDeps | B11: Has dependents | C11: =IF(C9+C10>0,"yes","no") -> no | H11: Florida | I11: FL
A12: childcare | B12: Paid childcare | C12: =IF(TRIM(Household!B8)="Yes",1,0) -> 0 | H12: Georgia | I12: GA
A13: wages | B13: W-2 wages plus unreported cash tips | C13: =Jobs!C16+Income!C24 -> 0 | H13: Hawaii | I13: HI
A14: withheld | B14: Federal tax withheld | C14: =Jobs!D16 -> 0 | H14: Idaho | I14: ID
A15: stateWithheld | B15: State tax withheld | C15: =Jobs!E16 -> 0 | H15: Illinois | I15: IL
A16: tips | B16: Tips (W-2 and cash) | C16: =Jobs!F16+Income!C24 -> 0 | H16: Indiana | I16: IN
A17: overtimePremium | B17: Overtime premium | C17: =Jobs!G16 -> 0 | H17: Iowa | I17: IA
A18: seIncome | B18: Self-employment income | C18: =Income!C19 -> 0 | H18: Kansas | I18: KS
A19: seExpenses | B19: Deductible business expenses | C19: =Expenses!E79 -> 0 | H19: Kentucky | I19: KY
A20: estimatedPayments | B20: Federal estimated payments | C20: =Payments!B9 -> 0 | H20: Louisiana | I20: LA
A21: stateEstimated | B21: State estimated payments | C21: =Payments!D9 -> 0 | H21: Maine | I21: ME
A22: isTrucker | B22: Logged truck driver trips | C22: =IF(Trips!D36+Trips!E36>0,1,0) -> 0 | H22: Maryland | I22: MD
A23: perDiemFull | B23: Full days away (Canada days converted to $80 days) | C23: =ROUND(Trips!D36-Trips!C36+Trips!C36*C41/C40,2) -> 0 | H23: Massachusetts | I23: MA
A24: perDiemPartial | B24: Travel days (75%) | C24: =Trips!E36 -> 0 | H24: Michigan | I24: MI
A25: interest | B25: Bank interest | C25: =Income!C25 -> 0 | H25: Minnesota | I25: MN
A26: unemployment | B26: Unemployment | C26: =Income!C26 -> 0 | H26: Mississippi | I26: MS
A27: otherIncome | B27: Retirement withdrawals and other income | C27: =Income!C27+Income!C28 -> 0 | H27: Missouri | I27: MO
A28: retirement | B28: Has retirement withdrawals | C28: =IF(Income!C27>0,1,0) -> 0 | H28: Montana | I28: MT
A29: hasInvestments | B29: Did you sell stocks or crypto, or receive dividends? | C29: =IF(TRIM(Checklist!B4)="Yes",1,0) -> 0 | H29: Nebraska | I29: NE
A30: mortgage | B30: Did you pay mortgage interest on your home? | C30: =IF(TRIM(Checklist!B5)="Yes",1,0) -> 0 | H30: Nevada | I30: NV
A31: studentLoan | B31: Did you pay student loan interest? | C31: =IF(TRIM(Checklist!B6)="Yes",1,0) -> 0 | H31: New Hampshire | I31: NH
A32: college | B32: Did you pay college tuition for yourself or a dependent? | C32: =IF(TRIM(Checklist!B7)="Yes",1,0) -> 0 | H32: New Jersey | I32: NJ
A33: marketplace | B33: Did anyone on your return have Marketplace health insurance (Form 1095-A)? | C33: =IF(TRIM(Checklist!B8)="Yes",1,0) -> 0 | H33: New Mexico | I33: NM
A34: noSsn | B34: Does anyone on the return NOT have a Social Security number? | C34: =IF(TRIM(Checklist!B9)="Yes",1,0) -> 0 | H34: New York | I34: NY
A35: irsLetter | B35: Did you receive a letter from the IRS or the state? | C35: =IF(TRIM(Checklist!B10)="Yes",1,0) -> 0 | H35: North Carolina | I35: NC
H36: North Dakota | I36: ND
H37: Ohio | I37: OH
H38: Oklahoma | I38: OK
A39: Per diem rates (IRS Notice 2026-60) | H39: Oregon | I39: OR
B40: U.S. daily rate | C40: 80 | H40: Pennsylvania | I40: PA
...
